Workbook

Sheet Retos
A1: id | B1: texto | C1: variante_corta | D1: virtud | E1: subcomponente | F1: facultad | G1: ambito | H1: tipo | I1: intensidad | J1: minutos_estimados | K1: requiere_otra_persona | L1: disparador_contextual | M1: dif_colerico | N1: dif_melancolico | O1: dif_sanguineo | P1: dif_flematico | Q1: obstaculo_que_combate | R1: repetible | S1: pregunta_examen | T1: fuente_libro | U1: fuente_seccion | V1: cita_literal
A2: pru-01 | B2: Antes de tomar hoy una decisión que afecte a otros, pide la opinión de al menos una persona y escúchala hasta el final sin interrumpir. | C2: Pide consejo antes de decidir | D2: prudencia | E2: deliberacion | F2: razon | G2: trabajo | H2: accion | I2: =ROUND(AVERAGE(M2:P2),0) -> 3 | J2: 10 | K2: sí | L2: reunión o decisión del día | M2: 5 | N2: 2 | O2: 3 | P2: 2 | Q2: autosatisfacción | R2: sí | S2: ¿Pedí consejo antes de decidir? Si no, ¿fue por prisa (primera reacción) o porque decidí no hacerlo? | T2: Del temperamento al carácter | U2: 3. El colérico: su desafío personal | V2: debe aprender a pedir consejo de forma habitual
A3: pru-02 | B3: Hoy toma una decisión que llevas aplazando. Fija la hora, decide y comunícala, aunque no tengas toda la información. | C3: Decide hoy lo aplazado | D3: prudencia | E3: decision | F3: razon | G3: trabajo | H3: accion | I3: =ROUND(AVERAGE(M3:P3),0) -> 3 | J3: 15 | K3: no | L3: asunto pendiente que se arrastra | M3: 1 | N3: 5 | O3: 2 | P3: 5 | Q3: perfeccionismo | R3: sí | S3: ¿Decidí? Si no, ¿qué certeza estaba esperando y era razonable esperarla? | T3: Del temperamento al carácter | U3: 4. El melancólico: su desafío personal | V3: El objetivo de la prudencia no es deliberar, sino decidir
A4: pru-03 | B4: Antes de dar por buena una información importante hoy, pregúntate de dónde viene y si es un hecho o una opinión. Anótalo. | C4: Distingue hechos de opiniones | D4: prudencia | E4: deliberacion | F4: razon | G4: trabajo | H4: accion | I4: =ROUND(AVERAGE(M4:P4),0) -> 3 | J4: 5 | K4: no | L4: noticia, informe o rumor recibido | M4: 3 | N4: 2 | O4: 4 | P4: 2 | R4: sí | S4: ¿Separé hechos de opiniones antes de decidir o repetí lo que oí? | T4: Creado para la grandeza | U4: Pasos prácticos: Prudencia | V4: ¿Hago distinciones entre hechos y opiniones, verdades y medias verdades?
A5: pru-04 | B5: Identifica hoy una verdad incómoda que estás evitando mirar (sobre un proyecto, una relación, tu salud). Escríbela en una frase. | C5: Mira la verdad incómoda | D5: prudencia | E5: deliberacion | F5: razon | G5: vida interior | H5: contemplacion | I5: =ROUND(AVERAGE(M5:P5),0) -> 3 | J5: 10 | K5: no | M5: 3 | N5: 2 | O5: 4 | P5: 3 | Q5: conformismo | R5: no | S5: ¿Escribí la verdad incómoda tal como es, sin suavizarla? | T5: Creado para la grandeza | U5: Pasos prácticos: Prudencia | V5: ¿Rechazo las verdades que me cuesta aceptar?
A6: pru-05 | B6: Cuando algo salga mal hoy, nombra tu parte de responsabilidad en voz alta o por escrito antes de hablar de la de los demás. | C6: Asume tu parte primero | D6: prudencia | E6: decision | F6: razon | G6: trabajo | H6: accion | I6: =ROUND(AVERAGE(M6:P6),0) -> 3 | J6: 5 | K6: sí | L6: error o contratiempo | M6: 5 | N6: 2 | O6: 3 | P6: 2 | R6: sí | S6: ¿Nombré mi responsabilidad antes de señalar a otros? | T6: Creado para la grandeza | U6: Pasos prácticos: Prudencia | V6: Si las cosas van mal, ¿evito acusar a los demás?
A7: pru-06 | B7: Hoy, antes de responder a una propuesta ajena, repite con tus palabras lo que la otra persona ha dicho y pregúntale si lo has entendido bien. | C7: Repite antes de responder | D7: prudencia | E7: deliberacion | F7: razon | G7: trabajo | H7: accion | I7: =ROUND(AVERAGE(M7:P7),0) -> 3 | J7: 5 | K7: sí | L7: conversación con desacuerdo | M7: 5 | N7: 3 | O7: 3 | P7: 2 | R7: sí | S7: ¿Comprobé que había entendido antes de responder? | T7: Del temperamento al carácter | U7: 3. El colérico: su desafío personal | V7: Precisa humildad para escuchar a las personas y comprenderlas
A8: pru-07 | B8: Elige una decisión pequeña que te esté costando y date un límite: diez minutos de reflexión y luego actúa, pase lo que pase. | C8: Diez minutos y actúa | D8: prudencia | E8: decision | F8: razon | G8: trabajo | H8: accion | I8: =ROUND(AVERAGE(M8:P8),0) -> 3 | J8: 10 | K8: no | L8: indecisión ante algo menor | M8: 1 | N8: 5 | O8: 2 | P8: 5 | Q8: perfeccionismo | R8: sí | S8: ¿Respeté el límite de tiempo y actué? | T8: Del temperamento al carácter | U8: 4. El melancólico: su desafío personal | V8: Hamlet siempre le falta información
A9: pru-08 | B9: Pregunta hoy a alguien con más experiencia cómo resolvió una situación parecida a la que tienes entre manos. | C9: Aprende de la experiencia ajena | D9: prudencia | E9: deliberacion | F9: razon | G9: trabajo | H9: accion | I9: =ROUND(AVERAGE(M9:P9),0) -> 3 | J9: 15 | K9: sí | L9: problema nuevo | M9: 4 | N9: 3 | O9: 2 | P9: 2 | Q9: autosatisfacción | R9: sí | S9: ¿Pregunté y escuché, o preferí resolverlo solo? | T9: Creado para la grandeza | U9: Pasos prácticos: Prudencia | V9: ¿Soy lo bastante humilde como para aprender de la experiencia ajena?
A10: pru-09 | B10: Antes de una decisión de hoy, enumera por escrito las tres dificultades reales y tacha las que solo existen en tu imaginación. | C10: Tacha los problemas imaginarios | D10: prudencia | E10: deliberacion | F10: razon | G10: vida interior | H10: contemplacion | I10: =ROUND(AVERAGE(M10:P10),0) -> 3 | J10: 10 | K10: no | L10: preocupación recurrente | M10: 2 | N10: 5 | O10: 2 | P10: 4 | R10: sí | S10: ¿Cuántas dificultades quedaron tras tachar? ¿Era tan grave como sentía? | T10: Del temperamento al carácter | U10: 4. El melancólico: su desafío personal | V10: El 90% de los problemas que me hacen sentir mal solo existen en mi imaginación
A11: pru-10 | B11: Hoy, en un asunto donde estás seguro de tener razón, busca activamente un dato o argumento que te contradiga. | C11: Busca lo que te contradice | D11: prudencia | E11: deliberacion | F11: razon | G11: trabajo | H11: accion | I11: =ROUND(AVERAGE(M11:P11),0) -> 3 | J11: 10 | K11: no | L11: convicción fuerte | M11: 5 | N11: 3 | O11: 3 | P11: 2 | R11: sí | S11: ¿Encontré algo que me contradijera y lo tuve en cuenta? | T11: Creado para la grandeza | U11: Pasos prácticos: Prudencia | V11: ¿Soy suficientemente humilde como para reconocer y dejar a un lado mis prejuicios?
A12: pru-11 | B12: Antes de aceptar una propuesta que te entusiasma, enumera tres razones por las que podría no funcionar. | C12: Enfría el entusiasmo con datos | D12: prudencia | E12: deliberacion | F12: razon | G12: trabajo | H12: accion | I12: =ROUND(AVERAGE(M12:P12),0) -> 3 | J12: 10 | K12: no | L12: propuesta atractiva | M12: 3 | N12: 1 | O12: 5 | P12: 2 | R12: sí | S12: ¿Pensé seriamente en lo que podía fallar o dije 'esto va a funcionar' sin más? | T12: Del temperamento al carácter | U12: 5. El sanguíneo: su desafío personal | V12: debe esforzarse por vencer la superficialidad
A13: pru-12 | B13: Una vez tomada una decisión hoy, ponla en marcha antes de que acabe el día: un correo, una llamada, un primer paso. | C13: Ejecuta la decisión hoy | D13: prudencia | E13: decision | F13: razon | G13: trabajo | H13: accion | I13: =ROUND(AVERAGE(M13:P13),0) -> 3 | J13: 15 | K13: no | L13: decisión reciente | M13: 1 | N13: 4 | O13: 3 | P13: 4 | R13: sí | S13: ¿Di el primer paso el mismo día? | T13: Del temperamento al carácter | U13: 7. Desarrollo de la audacia | V13: No tardes en poner por obra tus decisiones
A14: aud-01 | B14: Hoy propón en voz alta una idea que llevas tiempo guardando, en una reunión o a alguien con capacidad de decidir. | C14: Di la idea que guardas | D14: fortaleza | E14: audacia | F14: voluntad | G14: trabajo | H14: accion | I14: =ROUND(AVERAGE(M14:P14),0) -> 3 | J14: 5 | K14: sí | L14: reunión de equipo | M14: 1 | N14: 5 | O14: 2 | P14: 4 | Q14: conformismo | R14: no | S14: ¿Dije mi idea? Si no, ¿qué temía exactamente? | T14: Del temperamento al carácter | U14: 7. Desarrollo de la audacia | V14: Comparte con todo el mundo lo que tienes en tu interior
A15: aud-02 | B15: Inicia hoy una conversación con alguien que no conoces o con quien hace tiempo que no hablas. | C15: Habla con alguien nuevo | D15: fortaleza | E15: audacia | F15: voluntad | G15: amistad | H15: accion | I15: =ROUND(AVERAGE(M15:P15),0) -> 3 | J15: 10 | K15: sí | M15: 1 | N15: 5 | O15: 1 | P15: 4 | R15: sí | S15: ¿Fui yo quien inició la conversación? | T15: Del temperamento al carácter | U15: 7. Desarrollo de la audacia | V15: No te aísles. Ve al encuentro de la gente
A16: aud-03 | B16: Toma hoy una decisión que implique un riesgo razonable en tu vida profesional y que venías evitando por miedo a equivocarte. | C16: Asume un riesgo razonable | D16: fortaleza | E16: audacia | F16: voluntad | G16: trabajo | H16: accion | I16: =ROUND(AVERAGE(M16:P16),0) -> 3 | J16: 20 | K16: no | L16: oportunidad que da miedo | M16: 1 | N16: 5 | O16: 2 | P16: 5 | Q16: perfeccionismo | R16: no | S16: ¿Asumí el riesgo? ¿Lo que me frenaba era prudencia o miedo a equivocarme? | T16: Del temperamento al carácter | U16: 6. El flemático: su desafío personal | V16: Debe practicar la audacia, porque la esencia de la prudencia no es la deliberación, sino la decisión
A17: aud-04 | B17: Hoy trata de frente un asunto difícil con una persona concreta, en lugar de rodearlo o posponerlo. | C17: Trata lo difícil de frente | D17: fortaleza | E17: audacia | F17: voluntad | G17: trabajo | H17: accion | I17: =ROUND(AVERAGE(M17:P17),0) -> 4 | J17: 15 | K17: sí | L17: conflicto latente | M17: 1 | N17: 4 | O17: 4 | P17: 5 | Q17: conformismo | R17: sí | S17: ¿Abordé el asunto directamente? | T17: Creado para la grandeza | U17: Pasos prácticos: Fortaleza | V17: ¿Reúno el valor para tratar directamente asuntos difíciles?
A18: aud-05 | B18: Escribe tu misión en una frase y léela en voz alta antes de empezar el día. Si no la tienes, escribe hoy un primer borrador. | C18: Lee tu misión en voz alta | D18: fortaleza | E18: audacia | F18: voluntad | G18: vida interior | H18: contemplacion | I18: =ROUND(AVERAGE(M18:P18),0) -> 3 | J18: 5 | K18: no | L18: inicio del día | M18: 2 | N18: 3 | O18: 3 | P18: 4 | R18: sí | S18: ¿Recordé mi misión y cambió algo en cómo actué? | T18: Del temperamento al carácter | U18: 7. Desarrollo de la audacia | V18: Transforma tu sueño en misión y recuérdate esta misión cada día
A19: aud-06 | B19: Comete hoy un error a propósito de ser rápido: entrega, publica o envía algo al 80 % de perfección en lugar de pulirlo más. | C19: Entrega al 80 % | D19: fortaleza | E19: audacia | F19: voluntad | G19: trabajo | H19: accion | I19: =ROUND(AVERAGE(M19:P19),0) -> 3 | J19: 15 | K19: no | L19: tarea que llevas puliendo | M19: 1 | N19: 5 | O19: 2 | P19: 4 | Q19: perfeccionismo | R19: sí | S19: ¿Entregué sin esperar la perfección? ¿Qué pasó? | T19: Del temperamento al carácter | U19: 4. El melancólico: su desafío personal | V19: Cuanto mejor es un hombre, tantos más errores comete
A20: aud-07 | B20: Defiende hoy tu punto de vista ante alguien con más autoridad que tú, con respeto y sin ceder por comodidad. | C20: Defiende tu postura ante autoridad | D20: fortaleza | E20: audacia | F20: voluntad | G20: trabajo | H20: accion | I20: =ROUND(AVERAGE(M20:P20),0) -> 4 | J20: 10 | K20: sí | L20: desacuerdo con un superior | M20: 2 | N20: 4 | O20: 3 | P20: 5 | Q20: conformismo | R20: no | S20: ¿Dije lo que pensaba o callé para evitar el conflicto? | T20: Del temperamento al carácter | U20: 6. El flemático: su desafío personal | V20: Evita los conflictos a cualquier precio
A21: aud-08 | B21: Hoy haz algo que te saque de tu rutina habitual: un camino distinto, un plan nuevo, una propuesta a tu familia. | C21: Rompe la rutina hoy | D21: fortaleza | E21: audacia | F21: voluntad | G21: familia | H21: accion | I21: =ROUND(AVERAGE(M21:P21),0) -> 3 | J21: 30 | K21: no | M21: 1 | N21: 3 | O21: 1 | P21: 5 | Q21: conformismo | R21: sí | S21: ¿Salí del statu quo por decisión propia? | T21: Del temperamento al carácter | U21: 6. El flemático: su desafío personal | V21: le gusta el statu quo, la seguridad, la rutina
A22: aud-09 | B22: Anima hoy a alguien de tu entorno a asumir un riesgo que le conviene, y ofrécele tu apoyo concreto. | C22: Anima a otro a arriesgar | D22: fortaleza | E22: audacia | F22: voluntad | G22: trabajo | H22: accion | I22: =ROUND(AVERAGE(M22:P22),0) -> 3 | J22: 10 | K22: sí | L22: colaborador indeciso | M22: 2 | N22: 3 | O22: 2 | P22: 4 | R22: sí | S22: ¿Animé a alguien a arriesgar en vez de protegerle? | T22: Creado para la grandeza | U22: Pasos prácticos: Fortaleza | V22: ¿Animo a otros a correr riesgos?
A23: aud-10 | B23: Da hoy un paso visible hacia un sueño que tienes aparcado: una llamada, una inscripción, un primer borrador. | C23: Un paso hacia el sueño aparcado | D23: fortaleza | E23: audacia | F23: voluntad | G23: vida interior | H23: accion | I23: =ROUND(AVERAGE(M23:P23),0) -> 4 | J23: 20 | K23: no | M23: 2 | N23: 5 | O23: 3 | P23: 5 | Q23: impaciencia | R23: no | S23: ¿Di el paso? ¿Qué excusa estuvo a punto de impedirlo? | T23: Coaching con Juana de Arco | U23: 4ª sesión: Hazte un plan de crecimiento | V23: Aprende a soñar
A24: aud-11 | B24: Cuando te veas pensando «¿quién soy yo para…?», completa la frase con lo que harías si no tuvieras miedo y hazlo hoy en versión pequeña. | C24: Actúa pese al '¿quién soy yo?' | D24: fortaleza | E24: audacia | F24: voluntad | G24: vida interior | H24: accion | I24: =ROUND(AVERAGE(M24:P24),0) -> 3 | J24: 15 | K24: no | L24: momento de pusilanimidad | M24: 1 | N24: 5 | O24: 2 | P24: 5 | Q24: conformismo | R24: sí | S24: ¿Detecté el pensamiento y actué a pesar de él? | T24: Coaching con Juana de Arco | U24: 3ª sesión: Humildad y magnanimidad | V24: Identifica los momentos de tu vida en los que te paralizaste por la modestia
A25: res-01 | B25: Termina hoy la tarea que tienes a medias antes de empezar ninguna nueva, cuidando los detalles finales. | C25: Termina lo que tienes a medias | D25: fortaleza | E25: resistencia | F25: voluntad | G25: trabajo | H25: accion | I25: =ROUND(AVERAGE(M25:P25),0) -> 3 | J25: 45 | K25: no | L25: tarea empezada y abandonada | M25: 2 | N25: 2 | O25: 5 | P25: 2 | R25: sí | S25: ¿La terminé del todo, con los detalles, o la dejé 'casi'? | T25: Del temperamento al carácter | U25: 7. Desarrolla la resistencia | V25: Termina el trabajo que te ocupa actualmente, cuidando los detalles
A26: res-02 | B26: Haz hoy primero lo importante y deja lo agradable para después, aunque lo agradable sea más urgente en apariencia. | C26: Lo importante antes que lo agradable | D26: fortaleza | E26: resistencia | F26: voluntad | G26: trabajo | H26: accion | I26: =ROUND(AVERAGE(M26:P26),0) -> 3 | J26: 60 | K26: no | L26: inicio de la jornada | M26: 2 | N26: 3 | O26: 5 | P26: 3 | R26: sí | S26: ¿Empecé por lo importante o por lo que me apetecía? | T26: Del temperamento al carácter | U26: 7. Desarrolla la resistencia | V26: Haz primero lo que es importante, y, lo que es agradable, hazlo después
A27: res-03 | B27: Sonríe hoy a alguien aunque no tengas ganas, y mantén el buen humor ante la primera contrariedad del día. | C27: Sonríe sin ganas | D27: fortaleza | E27: resistencia | F27: voluntad | G27: familia | H27: accion | I27: =ROUND(AVERAGE(M27:P27),0) -> 3 | J27: 1 | K27: sí | L27: mal humor matinal | M27: 3 | N27: 5 | O27: 2 | P27: 2 | R27: sí | S27: ¿Sonreí y mantuve el humor ante la contrariedad? | T27: Del temperamento al carácter | U27: 7. Desarrolla la resistencia | V27: Sonríe aunque no tengas ninguna gana
A28: res-04 | B28: Sé especialmente amable hoy con la persona que más te carga o te irrita. | C28: Amable con quien te irrita | D28: fortaleza | E28: resistencia | F28: voluntad | G28: trabajo | H28: accion | I28: =ROUND(AVERAGE(M28:P28),0) -> 3 | J28: 5 | K28: sí | L28: encuentro con persona difícil | M28: 4 | N28: 4 | O28: 3 | P28: 2 | Q28: falta de realismo | R28: sí | S28: ¿Fui amable de verdad o solo correcto? ¿Qué me costó más? | T28: Del temperamento al carácter | U28: 7. Desarrolla la resistencia | V28: Sé amable con los que te cargan
A29: res-05 | B29: Si hoy te llega una crítica o un comentario sobre ti, tómatelo con humor y no te defiendas. | C29: Ríete de lo que digan de ti | D29: fortaleza | E29: resistencia | F29: voluntad | G29: amistad | H29: omision | I29: =ROUND(AVERAGE(M29:P29),0) -> 4 | J29: 1 | K29: sí | L29: crítica recibida | M29: 4 | N29: 5 | O29: 3 | P29: 2 | R29: sí | S29: ¿Me reí o me defendí? ¿Cuánto duró el escozor? | T29: Del temperamento al carácter | U29: 7. Desarrolla la resistencia | V29: Acostúmbrate a tomarte en broma lo que otros dicen de ti
A30: res-06 | B30: Juega o dedica tiempo de verdad a tus hijos (o a alguien de tu familia) hoy, aunque llegues agotado. | C30: Juega aunque estés agotado | D30: fortaleza | E30: resistencia | F30: voluntad | G30: familia | H30: accion | I30: =ROUND(AVERAGE(M30:P30),0) -> 3 | J30: 20 | K30: sí | L30: llegada a casa cansado | M30: 3 | N30: 3 | O30: 3 | P30: 2 | R30: sí | S30: ¿Les dediqué tiempo real, sin móvil, a pesar del cansancio? | T30: Del temperamento al carácter | U30: 7. Desarrolla la resistencia | V30: Juega con tus hijos aunque estés muerto de cansancio
A31: res-07 | B31: Come hoy lo que te sirvan, sin quejas ni caprichos, y no comentes lo que no te gusta. | C31: Come sin caprichos | D31: fortaleza | E31: resistencia | F31: voluntad | G31: cuerpo | H31: omision | I31: =ROUND(AVERAGE(M31:P31),0) -> 3 | J31: 1 | K31: no | L31: comida en casa o fuera | M31: 2 | N31: 3 | O31: 4 | P31: 1 | R31: sí | S31: ¿Comí lo servido sin comentar ni rechazar? | T31: Del temperamento al carácter | U31: 7. Desarrolla la resistencia | V31: Come lo que te sirvan, sin caprichos
A32: res-08 | B32: Corrige hoy a alguien a tu cargo sobre algo que llevas tiempo dejando pasar, con caridad y sin rodeos. | C32: Corrige lo que llevas callando | D32: fortaleza | E32: resistencia | F32: voluntad | G32: trabajo | H32: accion | I32: =ROUND(AVERAGE(M32:P32),0) -> 4 | J32: 10 | K32: sí | L32: error repetido de un colaborador | M32: 2 | N32: 3 | O32: 5 | P32: 5 | Q32: conformismo | R32: no | S32: ¿Corregí con claridad y con afecto? ¿Qué me frenaba? | T32: Del temperamento al carácter | U32: 7. Desarrolla la resistencia | V32: Corrige a tus subordinados (con caridad), incluso si te cuesta
A33: res-09 | B33: Soporta hoy con buen humor una contrariedad concreta (retraso, cambio de planes, fallo técnico) sin quejarte en voz alta. | C33: Contrariedad sin queja | D33: fortaleza | E33: resistencia | F33: voluntad | G33: trabajo | H33: omision | I33: =ROUND(AVERAGE(M33:P33),0) -> 3 | J33: 1 | K33: no | L33: imprevisto | M33: 4 | N33: 4 | O33: 3 | P33: 1 | R33: sí | S33: ¿Me quejé en voz alta? ¿Cuántas veces? | T33: Del temperamento al carácter | U33: 7. Desarrolla la resistencia | V33: Soporta con buen humor las contrariedades, grandes y pequeñas
A34: res-10 | B34: Retoma hoy un proyecto personal que abandonaste y trabaja en él 25 minutos sin interrupciones. | C34: Retoma el proyecto abandonado | D34: fortaleza | E34: resistencia | F34: voluntad | G34: vida interior | H34: accion | I34: =ROUND(AVERAGE(M34:P34),0) -> 3 | J34: 25 | K34: no | M34: 2 | N34: 2 | O34: 5 | P34: 3 | R34: sí | S34: ¿Trabajé los 25 minutos completos? | T34: Del temperamento al carácter | U34: 5. El sanguíneo: su desafío personal | V34: Debe esforzarse por poner la última piedra en cada uno de sus proyectos
A35: res-11 | B35: Cumple hoy una promesa pequeña que hiciste y que te tienta no cumplir (una llamada, un favor, una hora acordada). | C35: Cumple la promesa pequeña | D35: fortaleza | E35: resistencia | F35: voluntad | G35: amistad | H35: accion | I35: =ROUND(AVERAGE(M35:P35),0) -> 3 | J35: 15 | K35: sí | L35: compromiso adquirido | M35: 2 | N35: 2 | O35: 5 | P35: 2 | R35: sí | S35: ¿Cumplí exactamente lo prometido y a tiempo? | T35: Del temperamento al carácter | U35: 5. El sanguíneo: su desafío personal | V35: Ha de practicar las virtudes de la resistencia y la fidelidad
A36: res-12 | B36: Mantén hoy una decisión ya tomada aunque surja oposición, sin reabrirla por comodidad. | C36: Mantén la decisión ante oposición | D36: fortaleza | E36: resistencia | F36: voluntad | G36: trabajo | H36: omision | I36: =ROUND(AVERAGE(M36:P36),0) -> 4 | J36: 5 | K36: sí | L36: crítica a una decisión | M36: 2 | N36: 4 | O36: 5 | P36: 4 | Q36: conformismo | R36: sí | S36: ¿Mantuve el rumbo o cedí para evitar fricción? | T36: Creado para la grandeza | U36: Pasos prácticos: Prudencia | V36: ¿Continúo fiel a mis decisiones sin importarme lo difícil que sea el camino?
A37: res-13 | B37: Defiende hoy la reputación de alguien ausente si oyes que se le critica injustamente. | C37: Defiende al ausente | D37: fortaleza | E37: resistencia | F37: voluntad | G37: trabajo | H37: accion | I37: =ROUND(AVERAGE(M37:P37),0) -> 4 | J37: 2 | K37: sí | L37: crítica a un ausente | M37: 2 | N37: 3 | O37: 4 | P37: 5 | Q37: conformismo | R37: sí | S37: ¿Salí en su defensa o callé para no incomodar? | T37: Creado para la grandeza | U37: Pasos prácticos: Fortaleza | V37: ¿Defiendo la reputación de quienes son víctima de rumores maliciosos?
A38: res-14 | B38: Dedica hoy un rato a una tarea tediosa pero necesaria que llevas evitando, y hazla bien hasta el final. | C38: La tarea tediosa, hasta el final | D38: fortaleza | E38: resistencia | F38: voluntad | G38: trabajo | H38: accion | I38: =ROUND(AVERAGE(M38:P38),0) -> 3 | J38: 30 | K38: no | M38: 2 | N38: 3 | O38: 5 | P38: 2 | R38: sí | S38: ¿La terminé con cuidado o la despaché deprisa? | T38: Liderazgo virtuoso | U38: Capítulo 4: Justicia y deberes ordinarios | V38: Los líderes buscan la perfección en su trabajo
A39: res-15 | B39: Vive cada hora de hoy como un capítulo nuevo: si fallas en algo por la mañana, empieza de cero por la tarde sin arrastrar el desánimo. | C39: Empieza de cero tras fallar | D39: fortaleza | E39: resistencia | F39: voluntad | G39: vida interior | H39: contemplacion | I39: =ROUND(AVERAGE(M39:P39),0) -> 3 | J39: 2 | K39: no | L39: fallo o error propio | M39: 3 | N39: 5 | O39: 2 | P39: 3 | Q39: perfeccionismo | R39: sí | S39: Tras un fallo, ¿me levanté rápido o me quedé en el desánimo? | T39: Liderazgo virtuoso | U39: Capítulo 2: Un programa para ganar | V39: Debemos considerar cada día, cada hora, como un nuevo capítulo de nuestra vida
A40: dom-01 | B40: Si hoy te contradicen, cuenta hasta diez antes de responder y hazlo en un tono más bajo del que te pide el cuerpo. | C40: Diez segundos antes de responder | D40: dominio de sí | F40: voluntad | G40: trabajo | H40: omision | I40: =ROUND(AVERAGE(M40:P40),0) -> 3 | J40: 1 | K40: sí | L40: opinión contraria a la tuya | M40: 5 | N40: 3 | O40: 2 | P40: 1 | R40: sí | S40: ¿Conté y bajé el tono? ¿La primera reacción fue física o decidí reaccionar así? | T40: Del temperamento al carácter | U40: 3. El colérico: su desafío personal | V40: no interpretar la opinión del otro como una declaración de guerra
...

Sheet Catálogo
A1: Virtudes
A2: virtud | B2: subcomponentes | C2: facultad | D2: qué permite (Liderazgo virtuoso) | E2: fuente
A3: prudencia | B3: deliberacion / decision | C3: razon | D3: Tomar buenas decisiones | E3: Liderazgo virtuoso
A4: fortaleza | B4: audacia / resistencia | C4: voluntad | D4: Mantener el rumbo y resistir presiones | E4: Liderazgo virtuoso
A5: dominio de sí | B5: — | C5: voluntad | D5: Sujetar las pasiones al espíritu y dirigirlas a la misión | E5: Liderazgo virtuoso
A6: justicia | B6: comunión / bien común | C6: voluntad | D6: Dar a cada uno lo suyo y entrar en el corazón de los demás | E6: Liderazgo virtuoso
A7: magnanimidad | B7: contemplación / acción | C7: corazon | D7: Responder a la vocación, realizar la misión, fijar metas altas | E7: Liderazgo virtuoso
A8: humildad | B8: fundamental (conocimiento de sí) / fraternal (servicio) | C8: corazon | D8: Superar el ego y servir a los demás de manera habitual | E8: Liderazgo virtuoso
A11: Temperamentos
A12: temperamento | B12: orientación | C12: virtud-reto | D12: puntos débiles clave | E12: fuente
A13: colérico | B13: Acción | C13: humildad | D13: Orgullo e ira; decide sin deliberar; activismo ciego; no reconoce errores; le cuesta servir | E13: Del temperamento al carácter
A14: melancólico | B14: Idea | C14: audacia | D14: Teme la acción y el riesgo; pesimismo; se inquieta por nimiedades; crítica y susceptibilidad; mal en equipo | E14: Del temperamento al carácter
A15: sanguíneo | B15: Personas | C15: resistencia | D15: Inconstancia; empieza y no termina; superficialidad; controla mal los sentidos externos; quiere agradar | E15: Del temperamento al carácter
A16: flemático | B16: Paz | C16: magnanimidad | D16: Statu quo; evita conflictos; miedo a equivocarse; apatía; no sabe soñar | E16: Del temperamento al carácter
A19: Perfiles combinados (dominante-secundario)
A20: perfil | B20: temperamentos | C20: virtud-reto | D20: fuente
A21: Contemplativo | B21: melancólico | C21: audacia | D21: Grandir avec son tempérament
A22: Contemplativo activo | B22: melancólico-colérico | C22: humildad fraternal | D22: Grandir avec son tempérament
A23: Contemplativo pragmático | B23: melancólico-flemático | C23: audacia | D23: Grandir avec son tempérament
A24: Comunicador | B24: sanguíneo | C24: resistencia | D24: Grandir avec son tempérament
A25: Comunicador focalizado | B25: sanguíneo-colérico | C25: humildad fundamental | D25: Grandir avec son tempérament
A26: Comunicador discreto | B26: sanguíneo-flemático | C26: magnanimidad | D26: Grandir avec son tempérament
A27: Mediador | B27: flemático | C27: magnanimidad | D27: Grandir avec son tempérament
A28: Mediador contemplativo | B28: flemático-melancólico | C28: audacia | D28: Grandir avec son tempérament
A31: Ámbitos
A32: ámbito | B32: descripción
A33: trabajo | B33: Vida profesional, equipo, colaboradores, decisiones
A34: familia | B34: Pareja, hijos, hogar
A35: amistad | B35: Amigos, relaciones personales
A36: vida interior | B36: Conocimiento propio, misión, examen, oración o meditación
A37: cultura | B37: Lecturas, música, pantallas, belleza, ambiente
A38: cuerpo | B38: Comida, descanso, sentidos, comodidades
A39: sociedad | B39: Comunidad, bien común, obligaciones cívicas
A42: Obstáculos (Liderazgo virtuoso, cap. 'Un programa para ganar' + 'Del temperamento al carácter')
A43: obstáculo | B43: descripción
A44: conformismo | B44: Nadar con la corriente; miedo al qué dirán
A45: perfeccionismo | B45: No aceptar el fallo; abandonar tras el error; fruto del orgullo
A46: impaciencia | B46: Querer que la virtud madure deprisa
A47: falta de realismo | B47: Olvidar que las personas difíciles son colaboradores en nuestro crecimiento
A48: autosatisfacción | B48: Creer que ya se hace bastante
...

Sheet Resumen
A1: Resumen de la biblioteca
A2: Total de retos | B2: =COUNTA(Retos!A2:A114) -> 113
A4: virtud | B4: nº retos | C4: intensidad media | D4: % del total
A5: prudencia | B5: =COUNTIF(Retos!$D$2:$D$114,A5) -> 13 | C5: =IFERROR(ROUND(AVERAGEIF(Retos!$D$2:$D$114,A5,Retos!$I$2:$I$114),1),"") -> 3.1 | D5: =IFERROR(B5/$B$2,0) -> 0.11504425
A6: fortaleza | B6: =COUNTIF(Retos!$D$2:$D$114,A6) -> 29 | C6: =IFERROR(ROUND(AVERAGEIF(Retos!$D$2:$D$114,A6,Retos!$I$2:$I$114),1),"") -> 3.3 | D6: =IFERROR(B6/$B$2,0) -> 0.25663717
A7: dominio de sí | B7: =COUNTIF(Retos!$D$2:$D$114,A7) -> 15 | C7: =IFERROR(ROUND(AVERAGEIF(Retos!$D$2:$D$114,A7,Retos!$I$2:$I$114),1),"") -> 3.1 | D7: =IFERROR(B7/$B$2,0) -> 0.13274336
A8: justicia | B8: =COUNTIF(Retos!$D$2:$D$114,A8) -> 15 | C8: =IFERROR(ROUND(AVERAGEIF(Retos!$D$2:$D$114,A8,Retos!$I$2:$I$114),1),"") -> 3.2 | D8: =IFERROR(B8/$B$2,0) -> 0.13274336
A9: magnanimidad | B9: =COUNTIF(Retos!$D$2:$D$114,A9) -> 20 | C9: =IFERROR(ROUND(AVERAGEIF(Retos!$D$2:$D$114,A9,Retos!$I$2:$I$114),1),"") -> 3.2 | D9: =IFERROR(B9/$B$2,0) -> 0.17699115
A10: humildad | B10: =COUNTIF(Retos!$D$2:$D$114,A10) -> 21 | C10: =IFERROR(ROUND(AVERAGEIF(Retos!$D$2:$D$114,A10,Retos!$I$2:$I$114),1),"") -> 3.3 | D10: =IFERROR(B10/$B$2,0) -> 0.18584071
A11: Total | B11: =SUM(B5:B10) -> 113
A13: ámbito | B13: nº retos
A14: trabajo | B14: =COUNTIF(Retos!$G$2:$G$114,A14) -> 56
A15: familia | B15: =COUNTIF(Retos!$G$2:$G$114,A15) -> 11
A16: amistad | B16: =COUNTIF(Retos!$G$2:$G$114,A16) -> 10
A17: vida interior | B17: =COUNTIF(Retos!$G$2:$G$114,A17) -> 23
A18: cultura | B18: =COUNTIF(Retos!$G$2:$G$114,A18) -> 5
A19: cuerpo | B19: =COUNTIF(Retos!$G$2:$G$114,A19) -> 3
A20: sociedad | B20: =COUNTIF(Retos!$G$2:$G$114,A20) -> 5
A23: tipo | B23: nº retos
A24: accion | B24: =COUNTIF(Retos!$H$2:$H$114,A24) -> 81
A25: omision | B25: =COUNTIF(Retos!$H$2:$H$114,A25) -> 14
A26: contemplacion | B26: =COUNTIF(Retos!$H$2:$H$114,A26) -> 18
A29: temperamento | B29: retos con dificultad ≥4 (los que más le cuestan) | C29: dificultad media
A30: colérico | B30: =COUNTIF(Retos!$M$2:$M$114,">=4") -> 46 | C30: =ROUND(AVERAGE(Retos!$M$2:$M$114),2) -> 3.14
A31: melancólico | B31: =COUNTIF(Retos!$N$2:$N$114,">=4") -> 47 | C31: =ROUND(AVERAGE(Retos!$N$2:$N$114),2) -> 3.33
A32: sanguíneo | B32: =COUNTIF(Retos!$O$2:$O$114,">=4") -> 36 | C32: =ROUND(AVERAGE(Retos!$O$2:$O$114),2) -> 3.04
A33: flemático | B33: =COUNTIF(Retos!$P$2:$P$114,">=4") -> 40 | C33: =ROUND(AVERAGE(Retos!$P$2:$P$114),2) -> 3.05

Sheet Leyenda
A1: Objeto | B1: Biblioteca de retos diarios derivada de los libros de Alexandre Dianine-Havard (Liderazgo virtuoso, Creado para la grandeza, Del temperamento al carácter, Coaching con Juana de Arco, Corazón libre, Grandir avec son tempérament).
A2: id | B2: Identificador único. Prefijo = virtud o bloque (pru, aud, res, dom, jus, mag, hum, esp = transversal, gt = perfiles combinados).
A3: texto / variante_corta | B3: Reto formulado para hoy, en segunda persona. La variante corta sirve para notificación.
A4: virtud / subcomponente / facultad | B4: Según el marco del método. Facultad: corazón (humildad, magnanimidad), razón (prudencia), voluntad (fortaleza, dominio de sí, justicia).
A5: intensidad | B5: Fórmula: media redondeada de las cuatro dificultades por temperamento. No editar a mano.
A6: dif_* (1–5) | B6: Cuánto cuesta este reto a cada temperamento. 1 = casi natural; 5 = va contra su inclinación. Estimación editorial a partir de los capítulos 'su desafío personal'. Revisable.
A7: disparador_contextual | B7: Situación del día en la que el reto encaja mejor. El motor de selección lo cruza con la agenda del usuario.
A8: obstaculo_que_combate | B8: Uno de los siete obstáculos del catálogo, cuando aplica.
A9: repetible | B9: sí = puede proponerse varias veces en un trimestre; no = reto de una sola vez o de baja frecuencia.
A10: pregunta_examen | B10: Pregunta para el examen de conciencia nocturno; pensada para distinguir fallo de temperamento (primera reacción) y fallo de carácter (decisión).
A11: fuente | B11: Libro, sección y cita breve que respaldan el reto. La cita es orientativa; verificar contra la edición en uso.
A12: Edición | B12: Las celdas de datos tienen validación de lista para virtud, facultad, tipo, ámbito y dificultades (1–5). Añadir filas al final de la tabla 'Retos'; el Resumen se recalcula solo.
